2023-12-01 23:20:23,416 INFO    StreamThr :10611 [internal.py:wandb_internal():86] W&B internal server running at pid: 10611, started at: 2023-12-01 23:20:23.415187
2023-12-01 23:20:23,416 DEBUG   HandlerThread:10611 [handler.py:handle_request():146] handle_request: status
2023-12-01 23:20:23,418 INFO    WriterThread:10611 [datastore.py:open_for_write():85] open: /Users/simonmenzi/Documents/RW/7. Semester/Bachelor Thesis/MyNEMPython/wandb/run-20231201_232023-87sx451r/run-87sx451r.wandb
2023-12-01 23:20:23,418 DEBUG   SenderThread:10611 [sender.py:send():380] send: header
2023-12-01 23:20:23,429 DEBUG   SenderThread:10611 [sender.py:send():380] send: run
2023-12-01 23:20:26,687 INFO    SenderThread:10611 [retry.py:__call__():172] Retry attempt failed:
Traceback (most recent call last):
  File "/opt/homebrew/lib/python3.11/site-packages/urllib3/connection.py", line 203, in _new_conn
    sock = connection.create_connection(
           ^^^^^^^^^^^^^^^^^^^^^^^^^^^^^
  File "/opt/homebrew/lib/python3.11/site-packages/urllib3/util/connection.py", line 60, in create_connection
    for res in socket.getaddrinfo(host, port, family, socket.SOCK_STREAM):
               ^^^^^^^^^^^^^^^^^^^^^^^^^^^^^^^^^^^^^^^^^^^^^^^^^^^^^^^^^^
  File "/opt/homebrew/Cellar/python@3.11/3.11.4/Frameworks/Python.framework/Versions/3.11/lib/python3.11/socket.py", line 962, in getaddrinfo
    for res in _socket.getaddrinfo(host, port, family, type, proto, flags):
               ^^^^^^^^^^^^^^^^^^^^^^^^^^^^^^^^^^^^^^^^^^^^^^^^^^^^^^^^^^^
socket.gaierror: [Errno 8] nodename nor servname provided, or not known

The above exception was the direct cause of the following exception:

Traceback (most recent call last):
  File "/opt/homebrew/lib/python3.11/site-packages/urllib3/connectionpool.py", line 791, in urlopen
    response = self._make_request(
               ^^^^^^^^^^^^^^^^^^^
  File "/opt/homebrew/lib/python3.11/site-packages/urllib3/connectionpool.py", line 492, in _make_request
    raise new_e
  File "/opt/homebrew/lib/python3.11/site-packages/urllib3/connectionpool.py", line 468, in _make_request
    self._validate_conn(conn)
  File "/opt/homebrew/lib/python3.11/site-packages/urllib3/connectionpool.py", line 1097, in _validate_conn
    conn.connect()
  File "/opt/homebrew/lib/python3.11/site-packages/urllib3/connection.py", line 611, in connect
    self.sock = sock = self._new_conn()
                       ^^^^^^^^^^^^^^^^
  File "/opt/homebrew/lib/python3.11/site-packages/urllib3/connection.py", line 210, in _new_conn
    raise NameResolutionError(self.host, self, e) from e
urllib3.exceptions.NameResolutionError: <urllib3.connection.HTTPSConnection object at 0x11c098510>: Failed to resolve 'api.wandb.ai' ([Errno 8] nodename nor servname provided, or not known)

The above exception was the direct cause of the following exception:

Traceback (most recent call last):
  File "/opt/homebrew/lib/python3.11/site-packages/requests/adapters.py", line 486, in send
    resp = conn.urlopen(
           ^^^^^^^^^^^^^
  File "/opt/homebrew/lib/python3.11/site-packages/urllib3/connectionpool.py", line 845, in urlopen
    retries = retries.increment(
              ^^^^^^^^^^^^^^^^^^
  File "/opt/homebrew/lib/python3.11/site-packages/urllib3/util/retry.py", line 515, in increment
    raise MaxRetryError(_pool, url, reason) from reason  # type: ignore[arg-type]
    ^^^^^^^^^^^^^^^^^^^^^^^^^^^^^^^^^^^^^^^^^^^^^^^^^^^
urllib3.exceptions.MaxRetryError: HTTPSConnectionPool(host='api.wandb.ai', port=443): Max retries exceeded with url: /graphql (Caused by NameResolutionError("<urllib3.connection.HTTPSConnection object at 0x11c098510>: Failed to resolve 'api.wandb.ai' ([Errno 8] nodename nor servname provided, or not known)"))

During handling of the above exception, another exception occurred:

Traceback (most recent call last):
  File "/opt/homebrew/lib/python3.11/site-packages/wandb/sdk/lib/retry.py", line 131, in __call__
    result = self._call_fn(*args, **kwargs)
             ^^^^^^^^^^^^^^^^^^^^^^^^^^^^^^
  File "/opt/homebrew/lib/python3.11/site-packages/wandb/sdk/internal/internal_api.py", line 366, in execute
    return self.client.execute(*args, **kwargs)  # type: ignore
           ^^^^^^^^^^^^^^^^^^^^^^^^^^^^^^^^^^^^
  File "/opt/homebrew/lib/python3.11/site-packages/wandb/vendor/gql-0.2.0/wandb_gql/client.py", line 52, in execute
    result = self._get_result(document, *args, **kwargs)
             ^^^^^^^^^^^^^^^^^^^^^^^^^^^^^^^^^^^^^^^^^^^
  File "/opt/homebrew/lib/python3.11/site-packages/wandb/vendor/gql-0.2.0/wandb_gql/client.py", line 60, in _get_result
    return self.transport.execute(document, *args, **kwargs)
           ^^^^^^^^^^^^^^^^^^^^^^^^^^^^^^^^^^^^^^^^^^^^^^^^^
  File "/opt/homebrew/lib/python3.11/site-packages/wandb/sdk/lib/gql_request.py", line 58, in execute
    request = self.session.post(self.url, **post_args)
              ^^^^^^^^^^^^^^^^^^^^^^^^^^^^^^^^^^^^^^^^
  File "/opt/homebrew/lib/python3.11/site-packages/requests/sessions.py", line 637, in post
    return self.request("POST", url, data=data, json=json, **kwargs)
           ^^^^^^^^^^^^^^^^^^^^^^^^^^^^^^^^^^^^^^^^^^^^^^^^^^^^^^^^^
  File "/opt/homebrew/lib/python3.11/site-packages/requests/sessions.py", line 589, in request
    resp = self.send(prep, **send_kwargs)
           ^^^^^^^^^^^^^^^^^^^^^^^^^^^^^^
  File "/opt/homebrew/lib/python3.11/site-packages/requests/sessions.py", line 703, in send
    r = adapter.send(request, **kwargs)
        ^^^^^^^^^^^^^^^^^^^^^^^^^^^^^^^
  File "/opt/homebrew/lib/python3.11/site-packages/requests/adapters.py", line 519, in send
    raise ConnectionError(e, request=request)
requests.exceptions.ConnectionError: HTTPSConnectionPool(host='api.wandb.ai', port=443): Max retries exceeded with url: /graphql (Caused by NameResolutionError("<urllib3.connection.HTTPSConnection object at 0x11c098510>: Failed to resolve 'api.wandb.ai' ([Errno 8] nodename nor servname provided, or not known)"))
2023-12-01 23:20:28,452 DEBUG   HandlerThread:10611 [handler.py:handle_request():146] handle_request: keepalive
2023-12-01 23:20:29,776 DEBUG   HandlerThread:10611 [handler.py:handle_request():146] handle_request: shutdown
2023-12-01 23:20:29,776 INFO    HandlerThread:10611 [handler.py:finish():866] shutting down handler
2023-12-01 23:20:30,460 INFO    WriterThread:10611 [datastore.py:close():294] close: /Users/simonmenzi/Documents/RW/7. Semester/Bachelor Thesis/MyNEMPython/wandb/run-20231201_232023-87sx451r/run-87sx451r.wandb
2023-12-01 23:20:41,099 INFO    SenderThread:10611 [dir_watcher.py:__init__():211] watching files in: /Users/simonmenzi/Documents/RW/7. Semester/Bachelor Thesis/MyNEMPython/wandb/run-20231201_232023-87sx451r/files
2023-12-01 23:20:41,099 INFO    SenderThread:10611 [sender.py:_start_run_threads():1124] run started: 87sx451r with start time 1701469223.416256
2023-12-01 23:20:41,099 INFO    SenderThread:10611 [sender.py:finish():1536] shutting down sender
2023-12-01 23:20:41,099 INFO    SenderThread:10611 [dir_watcher.py:finish():358] shutting down directory watcher
2023-12-01 23:20:42,104 INFO    SenderThread:10611 [dir_watcher.py:finish():388] scan: /Users/simonmenzi/Documents/RW/7. Semester/Bachelor Thesis/MyNEMPython/wandb/run-20231201_232023-87sx451r/files
2023-12-01 23:20:42,106 INFO    SenderThread:10611 [dir_watcher.py:finish():402] scan save: /Users/simonmenzi/Documents/RW/7. Semester/Bachelor Thesis/MyNEMPython/wandb/run-20231201_232023-87sx451r/files/config.yaml config.yaml
2023-12-01 23:20:42,107 INFO    SenderThread:10611 [file_pusher.py:finish():175] shutting down file pusher
2023-12-01 23:20:42,108 INFO    SenderThread:10611 [file_pusher.py:join():181] waiting for file pusher
2023-12-01 23:20:43,201 INFO    wandb-upload_0:10611 [upload_job.py:push():131] Uploaded file /Users/simonmenzi/Documents/RW/7. Semester/Bachelor Thesis/MyNEMPython/wandb/run-20231201_232023-87sx451r/files/config.yaml
2023-12-01 23:20:43,617 INFO    SenderThread:10611 [file_stream.py:finish():595] file stream finish called
2023-12-01 23:20:43,873 INFO    SenderThread:10611 [file_stream.py:finish():599] file stream finish is done
